Workbook

Sheet Executive Summary
A1: Executive Summary
A2: Voice-first CFO operating model | Version 1.0 | As of 2026-07-28 | USD / monthly unless noted
A4: MODEL STATUS | B4: =Checks!$B$3 -> READY — INPUTS NEEDED | D4: Selected scenario | E4: =Assumptions!$B$5 -> Expected | G4: Selected clients | H4: =Assumptions!$E$5 -> 10 | J4: Input gaps | K4: =COUNTIF(Checks!$F$7:$F$24,"NEEDS INPUT")+COUNTIF(Checks!$F$7:$F$24,"VERIFY") -> 11
A7: EXECUTIVE DECISION CARDS
A8: Starter price | B8: =Assumptions!$B$11 -> 149 | C8: Fixed cash floor | D8: ='Fixed Operating Costs'!$G$20 -> 49.99 | E8: 1-client cash profit | F8: ='Profitability Forecast'!$P$8 -> 65.1575 | G8: 1-client full-use profit | H8: ='Scenario Analysis'!$I$9 -> 37.86 | I8: Break-even clients | J8: ='Margins & Unit Economics'!$K$6 -> 1 | K8: Selected-scale MRR | L8: =KPIs!$F$6 -> 1490
A9: Base remains under $200 | C9: Excludes usage/vendor tiers | E9: Selected scenario | G9: Conservative scenario | I9: Selected unit model | K9: All-Starter forecast
A12: CFO READOUT | H12: PROFIT TREND — SELECTED SCENARIO
A13: Decision | B13: CFO conclusion | C13: Why it matters | D13: Action owner | E13: Timing | F13: Status | H13: Clients | I13: Cash profit | J13: Fully loaded profit
A14: Launch price | B14: $149 Starter / 100 minutes | C14: Covers the corrected cash floor and two hours of developer availability in the current model | D14: CEO | E14: Launch | F14: Recommended | H14: ='Profitability Forecast'!A8 -> 1 | I14: ='Profitability Forecast'!P8 -> 65.1575 | J14: ='Profitability Forecast'!Q8 -> 65.1575
A15: Call guardrail | B15: Two-minute default with warning, confirmation and escalation | C15: Protects minutes while preserving legitimate booking/transfer use cases | D15: Developer | E15: Before Tsunami | F15: Required | H15: ='Profitability Forecast'!A9 -> 2 | I15: ='Profitability Forecast'!P9 -> 183.055 | J15: ='Profitability Forecast'!Q9 -> 183.055
A16: Cost accounting | B16: Twilio reload is a prepayment, not fixed expense | C16: Prevents double-counting and false break-even conclusions | D16: CEO/CFO | E16: Now | F16: Corrected | H16: ='Profitability Forecast'!A10 -> 3 | I16: ='Profitability Forecast'!P10 -> 300.1525 | J16: ='Profitability Forecast'!Q10 -> 300.1525
A17: Unknown usage | B17: Claude tokens, Zapier tasks and website demo traffic remain open | C17: Profits shown are known-cost figures until telemetry is entered | D17: Developer | E17: Pilot | F17: Input needed | H17: ='Profitability Forecast'!A11 -> 5 | I17: ='Profitability Forecast'!P11 -> 534.3475 | J17: ='Profitability Forecast'!Q11 -> 534.3475
A18: Scale trigger | B18: Track developer care hours weekly | C18: Hire/contract before sustained utilization reaches 80% of productive capacity | D18: CEO/Developer | E18: Ongoing | F18: KPI | H18: ='Profitability Forecast'!A12 -> 10 | I18: ='Profitability Forecast'!P12 -> 1119.835 | J18: ='Profitability Forecast'!Q12 -> 1119.835
H19: ='Profitability Forecast'!A13 -> 15 | I19: ='Profitability Forecast'!P13 -> 1705.3225 | J19: ='Profitability Forecast'!Q13 -> 1705.3225
H20: ='Profitability Forecast'!A14 -> 20 | I20: ='Profitability Forecast'!P14 -> 2290.85 | J20: ='Profitability Forecast'!Q14 -> 2290.85
H21: ='Profitability Forecast'!A15 -> 30 | I21: ='Profitability Forecast'!P15 -> 3461.825 | J21: ='Profitability Forecast'!Q15 -> 3461.825
H22: ='Profitability Forecast'!A16 -> 50 | I22: ='Profitability Forecast'!P16 -> 5803.775 | J22: ='Profitability Forecast'!Q16 -> 5803.775
H23: ='Profitability Forecast'!A17 -> 100 | I23: ='Profitability Forecast'!P17 -> 11658.65 | J23: ='Profitability Forecast'!Q17 -> 11658.65
A25: HOW TO USE THIS HUB
A26: 1 | B26: Update only blue/yellow Assumptions cells.
A27: 2 | B27: Developer fills measured tokens, Zapier tasks and incremental hosting after instrumented pilots.
A28: 3 | B28: Review Checks until MODEL STATUS becomes PASS.
A29: 4 | B29: Use Scenario Analysis before changing price, minutes or maintenance allocations.
A30: 5 | B30: Do not treat fully loaded profit as complete until owner hourly value is entered.

Sheet Assumptions
A1: Assumptions
A2: Blue cells are editable. Yellow cells require confirmation before the model can be considered fully loaded.
A4: MODEL CONTROLS
A5: Selected scenario | B5: Expected | D5: Selected forecast clients | E5: 10 | G5: Values update the hub
A6: Currency | B6: USD | D6: Model basis | E6: Monthly | G6: As of 2026-07-28
A9: VOICE-FIRST PLAN DRIVERS — CFO RECOMMENDATION
A10: Metric | B10: Starter | C10: Growth | D10: Scale | E10: Unit | F10: Status | G10: Notes
A11: Monthly price | B11: 149 | C11: 199 | D11: 349 | E11: $ / month | F11: Proposed | G11: Starter remains below the $200 ceiling
A12: Setup fee | B12: 299 | C12: 499 | D12: 799 | E12: $ one-time | F12: Proposed | G12: Covers implementation, testing, knowledge setup and launch
A13: Included voice minutes | B13: 100 | C13: 250 | D13: 600 | E13: minutes / month | F13: Proposed | G13: Hard usage limits; no unlimited plan
A14: Phone numbers included | B14: 1 | C14: 1 | D14: 2 | E14: numbers | F14: Proposed | G14: Local US numbers
A15: Maximum AI call length | B15: 2 | C15: 2 | D15: 2 | E15: minutes / call | F15: Policy | G15: Soft warning, confirmation, then transfer/callback ticket or hang-up
A16: Platform care — developer | B16: 2 | C16: 4 | D16: 8 | E16: hours / month | F16: Capacity ceiling | G16: Availability pool, not guaranteed project labor
A17: Owner/client success time | B17: 0.5 | C17: 1 | D17: 2 | E17: hours / month | F17: Capacity ceiling | G17: Review tickets, update knowledge and client communication
A18: Onboarding — developer | B18: 6 | C18: 10 | D18: 16 | E18: hours / client | F18: Planning input | G18: Change after first 3 production implementations
A19: Onboarding — owner | B19: 3 | C19: 4 | D19: 6 | E19: hours / client | F19: Planning input | G19: Discovery, training and acceptance
A20: Target customer | B20: Small local business | C20: Growing service business | D20: Multi-location operation | F20: Positioning | G20: Voice-first managed AI support
A23: SCENARIO DRIVERS — EXPLICIT PLANNING ASSUMPTIONS
A24: Scenario | B24: Minute utilization | C24: Developer care utilization | D24: Owner time utilization | E24: Unresolved-call ticket rate | F24: Status | G24: Use
A25: Conservative | B25: 1 | C25: 1 | D25: 1 | E25: 0.3 | F25: Planning assumption | G25: Stress test: full limits and full care availability consumed
A26: Expected | B26: 0.65 | C26: 0.5 | D26: 0.5 | E26: 0.2 | F26: Planning assumption | G26: Operating forecast until real telemetry is available
A27: Efficient | B27: 0.4 | C27: 0.25 | D27: 0.25 | E27: 0.1 | F27: Planning assumption | G27: Automation works well and support demand is low
A29: Selected scenario output | B29: =$B$5 -> Expected
A30: Minute utilization | B30: {=INDEX($B$25:$B$27,MATCH($B$5,$A$25:$A$27,0))} -> 0.65
A31: Developer utilization | B31: {=INDEX($C$25:$C$27,MATCH($B$5,$A$25:$A$27,0))} -> 0.5
A32: Owner utilization | B32: {=INDEX($D$25:$D$27,MATCH($B$5,$A$25:$A$27,0))} -> 0.5
A33: Ticket rate | B33: {=INDEX($E$25:$E$27,MATCH($B$5,$A$25:$A$27,0))} -> 0.2
A36: VENDOR, LABOR AND SCALING INPUTS
A37: Input | B37: Value | C37: Unit | D37: Status | E37: Source | F37: Owner / action | G37: Notes
A38: Developer hourly rate | B38: 25 | C38: $ / hour | D38: User confirmed | E38: CEO instruction | F38: CEO | G38: Goal rate; keep below $30/hour
A39: Owner hourly value | B39: 0 | C39: $ / hour | D39: INPUT REQUIRED | E39: Not provided | F39: CEO | G39: 0 excludes owner opportunity cost from fully loaded profit
A40: Productive developer capacity | B40: 120 | C40: hours / month | D40: Planning input | E40: Management assumption | F40: CEO/Developer | G40: Update to actual sustainable delivery capacity
A41: Twilio inbound local call | B41: 0.0085 | C41: $ / minute | D41: Verified | E41: Twilio official | F41: CFO | G41: US receive-call rate
A42: Twilio local phone number | B42: 1.15 | C42: $ / number / month | D42: Verified | E42: Twilio official | F42: CFO | G42: US local number
A43: Twilio call recording | B43: 0.0025 | C43: $ / minute | D43: Verified optional | E43: Twilio official | F43: Developer | G43: Not included in base forecast until enabled
A44: Twilio Media Streams | B44: 0.0044 | C44: $ / minute | D44: Verify architecture | E44: Twilio official | F44: Developer | G44: Only include if the selected voice path uses Media Streams
A45: Claude Haiku 4.5 input | B45: 1 | C45: $ / million tokens | D45: Verified | E45: Anthropic official | F45: CFO | G45: Standard input token price
A46: Claude Haiku 4.5 output | B46: 5 | C46: $ / million tokens | D46: Verified | E46: Anthropic official | F46: CFO | G46: Standard output token price
A47: Claude input tokens per call minute | B47: 0 | C47: tokens / minute | D47: INPUT REQUIRED | E47: Production telemetry | F47: Developer | G47: Run instrumented calls and populate measured average
A48: Claude output tokens per call minute | B48: 0 | C48: tokens / minute | D48: INPUT REQUIRED | E48: Production telemetry | F48: Developer | G48: Run instrumented calls and populate measured average
...

Sheet Fixed Operating Costs
A1: Fixed Operating Costs
A2: Recurring cash floor only. Usage-sensitive voice costs are modeled in Profitability Forecast to avoid double counting.
A4: ACTIVE MONTHLY FIXED COSTS
A5: Category | B5: Vendor | C5: Line item | D5: Billing | E5: Source amount | F5: Cycle | G5: Monthly model cost | H5: Included? | I5: Source status | J5: CFO treatment
A6: Integration | B6: Zapier | C6: Professional 750 tasks | D6: Recurring | E6: =Assumptions!$B$49 -> 19.99 | F6: Monthly | G6: =Assumptions!$B$49 -> 19.99 | H6: Yes | I6: Verified | J6: Shared base; overages are variable
A7: Database | B7: Supabase | C7: Pro plan | D7: Recurring | E7: =Assumptions!$B$56 -> 25 | F7: Monthly | G7: =Assumptions!$B$56 -> 25 | H7: Yes | I7: Verified | J7: Shared base; incremental usage separately input
A8: Hosting | B8: Railway | C8: Hobby minimum | D8: Recurring | E8: =Assumptions!$B$54 -> 5 | F8: Monthly | G8: =Assumptions!$B$54 -> 5 | H8: Yes | I8: Verified | J8: Shared base; first $5 of usage included
A9: Website | B9: TBD | C9: Website/domain/monitoring | D9: Recurring | E9: =Assumptions!$B$58 -> 0 | F9: Monthly | G9: =Assumptions!$B$58 -> 0 | H9: Yes | I9: INPUT REQUIRED | J9: Included at entered value
A10: G&A | B10: TBD | C10: Bookkeeping/accounting | D10: Recurring | E10: =Assumptions!$B$64 -> 0 | F10: Monthly | G10: =Assumptions!$B$64 -> 0 | H10: Yes | I10: INPUT REQUIRED | J10: Included at entered value
A11: Risk | B11: TBD | C11: Insurance/compliance | D11: Recurring | E11: =Assumptions!$B$65 -> 0 | F11: Monthly | G11: =Assumptions!$B$65 -> 0 | H11: Yes | I11: INPUT REQUIRED | J11: Included at entered value
A12: Software | B12: TBD | C12: Other recurring SaaS | D12: Recurring | E12: =Assumptions!$B$66 -> 0 | F12: Monthly | G12: =Assumptions!$B$66 -> 0 | H12: Yes | I12: INPUT REQUIRED | J12: Included at entered value
A13: Voice | B13: Twilio | C13: Sole proprietor A2P | D13: Recurring | E13: 2 | F13: Monthly | G13: 0 | H13: No | I13: Legacy source | J13: SMS-only; exclude from voice base
A14: Voice | B14: Twilio | C14: A2P brand registration | D14: One-time | E14: 4.5 | F14: One-time | G14: 0 | H14: No | I14: Legacy source | J14: Not monthly; only if SMS is launched
A15: Cash | B15: Twilio | C15: Account funding/reload | D15: Prepayment | E15: 24.4375 | F15: As used | G15: 0 | H15: No | I15: Legacy source | J15: Cash deposit is not a fixed P&L expense
A16: Voice | B16: ElevenLabs | C16: Legacy annual Starter plan | D16: Legacy | E16: 50 | F16: Annual | G16: 0 | H16: No | I16: Superseded | J16: Replaced by current ElevenAgents cost curve
A17: Hosting | B17: Fly.io | C17: Alternative to Railway | D17: Usage based | E17: 0 | F17: Monthly | G17: 0 | H17: No | I17: Official pricing varies | J17: Do not run both hosts unless architecture requires it
A20: ACTIVE FIXED COST FLOOR | G20: =SUM(G6:G12) -> 49.99
A21: Historical workbook reported monthly total | B21: 80.594167
A22: CFO-corrected active fixed floor | B22: =G20 -> 49.99
A23: Difference / reclassification | B23: =B21-B22 -> 30.604167
A25: CFO correction | B25: The prior $80.59 figure mixed fixed subscriptions with a Twilio funding reload and an obsolete ElevenLabs plan. The forecast now treats usage and prepaid funding according to economic substance.

Sheet Per-Customer Costs
A1: Per-Customer Costs
A2: Selected-scenario unit economics. ElevenLabs is shown at the $0.08 incremental rate here; the scaling forecast optimizes shared plan tiers.
A4: MONTHLY UNIT ECONOMICS BY PLAN
A5: Plan | B5: Price | C5: Included min | D5: Scenario min | E5: Calls at cap | F5: Number | G5: Twilio | H5: ElevenLabs | I5: Claude | J5: Zapier tasks | K5: Zapier cost | L5: Host/DB inc. | M5: Developer | N5: Owner value | O5: Known cash cost | P5: Cash contribution | Q5: Fully loaded | R5: Cash margin
A6: Starter | B6: =Assumptions!$B$11 -> 149 | C6: =Assumptions!$B$13 -> 100 | D6: =C6*Assumptions!$B$30 -> 65 | E6: =D6/Assumptions!$B$15 -> 32.5 | F6: =Assumptions!$B$14*Assumptions!$B$42 -> 1.15 | G6: =D6*Assumptions!$B$41 -> 0.5525 | H6: =D6*Assumptions!$D$72 -> 5.2 | I6: =D6*((Assumptions!$B$47*Assumptions!$B$45/1000000)+(Assumptions!$B$48*Assumptions!$B$46/1000000)) -> 0 | J6: =E6*Assumptions!$B$52+E6*Assumptions!$B$33*Assumptions!$B$53 -> 0 | K6: =J6*Assumptions!$B$51 -> 0 | L6: =Assumptions!$B$55+Assumptions!$B$57 -> 0 | M6: =Assumptions!$B$16*Assumptions!$B$31*Assumptions!$B$38 -> 25 | N6: =Assumptions!$B$17*Assumptions!$B$32*Assumptions!$B$39 -> 0 | O6: =SUM(F6:I6,K6:M6) -> 31.9025 | P6: =B6-O6 -> 117.0975 | Q6: =P6-N6 -> 117.0975 | R6: =P6/B6 -> 0.78588926
A7: Growth | B7: =Assumptions!$C$11 -> 199 | C7: =Assumptions!$C$13 -> 250 | D7: =C7*Assumptions!$B$30 -> 162.5 | E7: =D7/Assumptions!$C$15 -> 81.25 | F7: =Assumptions!$C$14*Assumptions!$B$42 -> 1.15 | G7: =D7*Assumptions!$B$41 -> 1.38125 | H7: =D7*Assumptions!$D$72 -> 13 | I7: =D7*((Assumptions!$B$47*Assumptions!$B$45/1000000)+(Assumptions!$B$48*Assumptions!$B$46/1000000)) -> 0 | J7: =E7*Assumptions!$B$52+E7*Assumptions!$B$33*Assumptions!$B$53 -> 0 | K7: =J7*Assumptions!$B$51 -> 0 | L7: =Assumptions!$B$55+Assumptions!$B$57 -> 0 | M7: =Assumptions!$C$16*Assumptions!$B$31*Assumptions!$B$38 -> 50 | N7: =Assumptions!$C$17*Assumptions!$B$32*Assumptions!$B$39 -> 0 | O7: =SUM(F7:I7,K7:M7) -> 65.53125 | P7: =B7-O7 -> 133.46875 | Q7: =P7-N7 -> 133.46875 | R7: =P7/B7 -> 0.67069724
A8: Scale | B8: =Assumptions!$D$11 -> 349 | C8: =Assumptions!$D$13 -> 600 | D8: =C8*Assumptions!$B$30 -> 390 | E8: =D8/Assumptions!$D$15 -> 195 | F8: =Assumptions!$D$14*Assumptions!$B$42 -> 2.3 | G8: =D8*Assumptions!$B$41 -> 3.315 | H8: =D8*Assumptions!$D$72 -> 31.2 | I8: =D8*((Assumptions!$B$47*Assumptions!$B$45/1000000)+(Assumptions!$B$48*Assumptions!$B$46/1000000)) -> 0 | J8: =E8*Assumptions!$B$52+E8*Assumptions!$B$33*Assumptions!$B$53 -> 0 | K8: =J8*Assumptions!$B$51 -> 0 | L8: =Assumptions!$B$55+Assumptions!$B$57 -> 0 | M8: =Assumptions!$D$16*Assumptions!$B$31*Assumptions!$B$38 -> 100 | N8: =Assumptions!$D$17*Assumptions!$B$32*Assumptions!$B$39 -> 0 | O8: =SUM(F8:I8,K8:M8) -> 136.815 | P8: =B8-O8 -> 212.185 | Q8: =P8-N8 -> 212.185 | R8: =P8/B8 -> 0.60797994
A12: COST DEFINITION & DEVELOPER INPUTS
A13: Cost | B13: Included in forecast? | C13: Method | D13: Action
A14: Twilio inbound + numbers | B14: Yes | C14: Official US rate × modeled usage | D14: No action unless country/number type changes
A15: ElevenLabs | B15: Yes | C15: Forecast selects the least-cost official self-serve plan curve | D15: Review plan selection when concurrency becomes binding
A16: Claude | B16: Formula active; currently $0 | C16: Official token rate × measured tokens per minute | D16: Developer must populate Assumptions B47:B48
A17: Zapier overage | B17: Formula active; may be $0 | C17: Shared included tasks then account-specific overage | D17: Developer must populate workflow task counts and verify overage rate
A18: Owner opportunity cost | B18: Fully loaded only; currently $0 | C18: Owner hours × owner hourly value | D18: CEO must populate Assumptions B39

Sheet Pricing & Add-ons
A1: Pricing & Add-ons
A2: Customer-facing architecture with hard minute limits, a two-minute conversation policy and managed platform care.
A4: VOICE-FIRST MONTHLY PLANS
A5: Plan | B5: Monthly price | C5: Setup fee | D5: Minutes | E5: Max call | F5: Numbers | G5: Developer care | H5: Owner success | I5: 24/7 answering | J5: Callback ticket portal | K5: Booking | L5: Transfers | M5: Best for | N5: Guardrail
A6: Starter | B6: =Assumptions!$B$11 -> 149 | C6: =Assumptions!$B$12 -> 299 | D6: =Assumptions!$B$13 -> 100 | E6: =Assumptions!$B$15 -> 2 | F6: =Assumptions!$B$14 -> 1 | G6: =Assumptions!$B$16 -> 2 | H6: =Assumptions!$B$17 -> 0.5 | I6: Yes | J6: Yes | K6: Yes | L6: Basic | M6: Small local businesses | N6: Warn → confirm → ticket/transfer/hang up
A7: Growth | B7: =Assumptions!$C$11 -> 199 | C7: =Assumptions!$C$12 -> 499 | D7: =Assumptions!$C$13 -> 250 | E7: =Assumptions!$C$15 -> 2 | F7: =Assumptions!$C$14 -> 1 | G7: =Assumptions!$C$16 -> 4 | H7: =Assumptions!$C$17 -> 1 | I7: Yes | J7: Yes | K7: Yes | L7: Advanced | M7: Growing service businesses | N7: Same two-minute policy; configurable exceptions
A8: Scale | B8: =Assumptions!$D$11 -> 349 | C8: =Assumptions!$D$12 -> 799 | D8: =Assumptions!$D$13 -> 600 | E8: =Assumptions!$D$15 -> 2 | F8: =Assumptions!$D$14 -> 2 | G8: =Assumptions!$D$16 -> 8 | H8: =Assumptions!$D$17 -> 2 | I8: Yes | J8: Yes | K8: Yes | L8: Advanced routing | M8: Multi-location operations | N8: Custom routing with two-minute default
A9: Enterprise | B9: Custom | C9: Custom | D9: Custom | E9: Custom | F9: Custom | G9: Custom SLA | H9: Custom | I9: Yes | J9: Yes | K9: Custom | L9: Custom | M9: Large/regulated operations | N9: Contracted controls
A12: ADD-ONS & OVERAGES | H12: PLATFORM CARE INCLUDED
A13: Add-on | B13: Customer price | C13: Billing | D13: Cost treatment | E13: Status | F13: Notes | H13: Service | I13: Included | J13: Boundary | K13: Customer outcome
A14: 100 additional voice minutes | B14: 25 | C14: Monthly | D14: Usage flows through vendor rates | E14: Launch | F14: $0.25/min package | H14: System health monitoring | I14: Yes | J14: Routine monitoring | K14: Fewer silent failures
A15: Voice minute overage | B15: 0.3 | C15: Per minute | D15: Usage flows through vendor rates | E15: Launch | F15: Below Reception.ai's published $0.40/min overage benchmark | H15: AI prompt tuning | I15: Yes | J15: Within existing workflow | K15: Better call quality
A16: Additional local number | B16: 15 | C16: Monthly | D16: Twilio number cost + margin | E16: Launch | F16: One local US number | H16: Knowledge base updates | I16: Yes | J16: Normal monthly changes | K16: Current answers
A17: Additional department / routing tree | B17: 39 | C17: Monthly | D17: Support + workflow cost | E17: Launch | F17: Separate escalation logic | H17: Bug fixes | I17: Yes | J17: LumiLink platform defects | K17: Reliable service
A18: Extra platform care | B18: 85 | C18: Per hour | D18: Developer labor | E18: Launch | F18: Bill beyond included availability pool | H18: Integration monitoring | I18: Yes | J18: Existing supported integrations | K18: Stable workflows
A19: Priority support | B19: 49 | C19: Monthly | D19: Support capacity | E19: Launch | F19: Faster response target; no emergency SLA | H19: New feature development | I19: No | J19: Quoted separately | K19: Clear scope and economics
A20: E-commerce connector | B20: 29 | C20: Monthly | D20: Workflow/task usage | E20: Roadmap | F20: Shopify or WooCommerce; setup billed separately | H20: Custom department build | I20: Add-on | J20: Routing add-on or project | K20: Predictable customization
A21: E-commerce connector setup | B21: 149 | C21: One-time | D21: Developer onboarding labor | E21: Roadmap | F21: Per supported storefront | H21: Emergency support | I21: No base SLA | J21: Quoted contract | K21: Avoids uncapped obligations
A22: SMS follow-up package | B22: 25 | C22: Monthly + carrier use | D22: A2P + messaging pass-through | E22: Roadmap | F22: Do not enable until messaging compliance is confirmed
A23: Call recording + retention | B23: 19 | C23: Monthly | D23: Twilio recording + storage | E23: Roadmap | F23: Consent and retention policy required
A24: Website chat widget | B24: 49 | C24: Monthly | D24: Model + hosting usage | E24: Roadmap | F24: Pricing to validate after measured chat cost
A25: Multilingual voice | B25: 39 | C25: Monthly | D25: Voice/LLM usage | E25: Roadmap | F25: Language availability and quality testing required
A26: Custom workflow/integration | B26: 149 | C26: From / one-time | D26: Developer labor | E26: Launch | F26: Quote complexity above standard scope

Sheet Onboarding Economics
A1: Onboarding Economics
A2: One-time economics for implementation. Owner time remains excluded from fully loaded economics until the CEO enters an hourly value.
A4: SETUP ECONOMICS BY PLAN
A5: Plan | B5: Setup fee | C5: Dev hours | D5: Dev cost | E5: Owner hours | F5: Owner cost | G5: Other setup cost | H5: Cash setup cost | I5: Cash contribution | J5: Fully loaded contribution | K5: Cash margin
A6: Starter | B6: =Assumptions!$B$12 -> 299 | C6: =Assumptions!$B$18 -> 6 | D6: =C6*Assumptions!$B$38 -> 150 | E6: =Assumptions!$B$19 -> 3 | F6: =E6*Assumptions!$B$39 -> 0 | G6: 0 | H6: =D6+G6 -> 150 | I6: =B6-H6 -> 149 | J6: =I6-F6 -> 149 | K6: =I6/B6 -> 0.49832776
A7: Growth | B7: =Assumptions!$C$12 -> 499 | C7: =Assumptions!$C$18 -> 10 | D7: =C7*Assumptions!$B$38 -> 250 | E7: =Assumptions!$C$19 -> 4 | F7: =E7*Assumptions!$B$39 -> 0 | G7: 0 | H7: =D7+G7 -> 250 | I7: =B7-H7 -> 249 | J7: =I7-F7 -> 249 | K7: =I7/B7 -> 0.498998
A8: Scale | B8: =Assumptions!$D$12 -> 799 | C8: =Assumptions!$D$18 -> 16 | D8: =C8*Assumptions!$B$38 -> 400 | E8: =Assumptions!$D$19 -> 6 | F8: =E8*Assumptions!$B$39 -> 0 | G8: 0 | H8: =D8+G8 -> 400 | I8: =B8-H8 -> 399 | J8: =I8-F8 -> 399 | K8: =I8/B8 -> 0.49937422
A12: STARTER ONBOARDING CAPACITY & CASH REQUIREMENT
A13: New clients | B13: Setup revenue | C13: Developer hours | D13: Developer cash cost | E13: Owner hours | F13: Owner value | G13: Other setup cost | H13: Cash contribution | I13: Fully loaded contribution
A14: 1 | B14: =A14*$B$6 -> 299 | C14: =A14*$C$6 -> 6 | D14: =A14*$D$6 -> 150 | E14: =A14*$E$6 -> 3 | F14: =A14*$F$6 -> 0 | G14: =A14*$G$6 -> 0 | H14: =B14-D14-G14 -> 149 | I14: =H14-F14 -> 149
A15: 5 | B15: =A15*$B$6 -> 1495 | C15: =A15*$C$6 -> 30 | D15: =A15*$D$6 -> 750 | E15: =A15*$E$6 -> 15 | F15: =A15*$F$6 -> 0 | G15: =A15*$G$6 -> 0 | H15: =B15-D15-G15 -> 745 | I15: =H15-F15 -> 745
A16: 10 | B16: =A16*$B$6 -> 2990 | C16: =A16*$C$6 -> 60 | D16: =A16*$D$6 -> 1500 | E16: =A16*$E$6 -> 30 | F16: =A16*$F$6 -> 0 | G16: =A16*$G$6 -> 0 | H16: =B16-D16-G16 -> 1490 | I16: =H16-F16 -> 1490
A17: 20 | B17: =A17*$B$6 -> 5980 | C17: =A17*$C$6 -> 120 | D17: =A17*$D$6 -> 3000 | E17: =A17*$E$6 -> 60 | F17: =A17*$F$6 -> 0 | G17: =A17*$G$6 -> 0 | H17: =B17-D17-G17 -> 2980 | I17: =H17-F17 -> 2980

Sheet Profitability Forecast
A1: Profitability Forecast
A2: All-Starter launch forecast at the selected scenario. Includes shared-vendor plan optimization, fixed overhead, developer care and demo usage.
A4: Selected scenario | B4: =Assumptions!$B$5 -> Expected | C4: Starter price | D4: =Assumptions!$B$11 -> 149 | E4: Selected minute use | F4: =Assumptions!$B$30 -> 0.65 | G4: Selected dev use | H4: =Assumptions!$B$31 -> 0.5
A6: MONTHLY STARTER-CLIENT PROFITABILITY
A7: Clients | B7: Revenue | C7: Platform minutes | D7: Calls | E7: Numbers | F7: Twilio | G7: ElevenLabs | H7: Claude | I7: Zapier tasks | J7: Zapier overage | K7: Payment fees | L7: Host/DB inc. | M7: Developer | N7: Owner value | O7: Fixed opex | P7: Cash profit | Q7: Fully loaded | R7: Cash margin | S7: Dev FTE | T7: EL Starter | U7: EL Creator | V7: EL Pro | W7: EL Scale | X7: EL Business | Y7: Least-cost plan
A8: 1 | B8: =A8*Assumptions!$B$11 -> 149 | C8: =A8*Assumptions!$B$13*Assumptions!$B$30+Assumptions!$B$59 -> 65 | D8: =C8/Assumptions!$B$15 -> 32.5 | E8: =(A8*Assumptions!$B$14+Assumptions!$B$60)*Assumptions!$B$42 -> 2.3 | F8: =C8*Assumptions!$B$41 -> 0.5525 | G8: =MIN(T8:X8) -> 6 | H8: =C8*((Assumptions!$B$47*Assumptions!$B$45/1000000)+(Assumptions!$B$48*Assumptions!$B$46/1000000)) -> 0 | I8: =D8*Assumptions!$B$52+D8*Assumptions!$B$33*Assumptions!$B$53 -> 0 | J8: =MAX(0,I8-Assumptions!$B$50)*Assumptions!$B$51 -> 0 | K8: =B8*Assumptions!$B$61 -> 0 | L8: =A8*(Assumptions!$B$55+Assumptions!$B$57) -> 0 | M8: =A8*Assumptions!$B$16*Assumptions!$B$31*Assumptions!$B$38 -> 25 | N8: =A8*Assumptions!$B$17*Assumptions!$B$32*Assumptions!$B$39 -> 0 | O8: ='Fixed Operating Costs'!$G$20 -> 49.99 | P8: =B8-SUM(E8:H8,J8:M8,O8) -> 65.1575 | Q8: =P8-N8 -> 65.1575 | R8: =P8/B8 -> 0.43729866 | S8: =(A8*Assumptions!$B$16*Assumptions!$B$31)/Assumptions!$B$40 -> 0.0083333333 | T8: =Assumptions!$B$72+MAX(0,C8-Assumptions!$C$72)*Assumptions!$D$72 -> 6 | U8: =Assumptions!$B$73+MAX(0,C8-Assumptions!$C$73)*Assumptions!$D$73 -> 22 | V8: =Assumptions!$B$74+MAX(0,C8-Assumptions!$C$74)*Assumptions!$D$74 -> 99 | W8: =Assumptions!$B$75+MAX(0,C8-Assumptions!$C$75)*Assumptions!$D$75 -> 299 | X8: =Assumptions!$B$76+MAX(0,C8-Assumptions!$C$76)*Assumptions!$D$76 -> 990 | Y8: {=INDEX(Assumptions!$A$72:$A$76,MATCH(G8,T8:X8,0))} -> Starter
A9: 2 | B9: =A9*Assumptions!$B$11 -> 298 | C9: =A9*Assumptions!$B$13*Assumptions!$B$30+Assumptions!$B$59 -> 130 | D9: =C9/Assumptions!$B$15 -> 65 | E9: =(A9*Assumptions!$B$14+Assumptions!$B$60)*Assumptions!$B$42 -> 3.45 | F9: =C9*Assumptions!$B$41 -> 1.105 | G9: =MIN(T9:X9) -> 10.4 | H9: =C9*((Assumptions!$B$47*Assumptions!$B$45/1000000)+(Assumptions!$B$48*Assumptions!$B$46/1000000)) -> 0 | I9: =D9*Assumptions!$B$52+D9*Assumptions!$B$33*Assumptions!$B$53 -> 0 | J9: =MAX(0,I9-Assumptions!$B$50)*Assumptions!$B$51 -> 0 | K9: =B9*Assumptions!$B$61 -> 0 | L9: =A9*(Assumptions!$B$55+Assumptions!$B$57) -> 0 | M9: =A9*Assumptions!$B$16*Assumptions!$B$31*Assumptions!$B$38 -> 50 | N9: =A9*Assumptions!$B$17*Assumptions!$B$32*Assumptions!$B$39 -> 0 | O9: ='Fixed Operating Costs'!$G$20 -> 49.99 | P9: =B9-SUM(E9:H9,J9:M9,O9) -> 183.055 | Q9: =P9-N9 -> 183.055 | R9: =P9/B9 -> 0.61427852 | S9: =(A9*Assumptions!$B$16*Assumptions!$B$31)/Assumptions!$B$40 -> 0.016666667 | T9: =Assumptions!$B$72+MAX(0,C9-Assumptions!$C$72)*Assumptions!$D$72 -> 10.4 | U9: =Assumptions!$B$73+MAX(0,C9-Assumptions!$C$73)*Assumptions!$D$73 -> 22 | V9: =Assumptions!$B$74+MAX(0,C9-Assumptions!$C$74)*Assumptions!$D$74 -> 99 | W9: =Assumptions!$B$75+MAX(0,C9-Assumptions!$C$75)*Assumptions!$D$75 -> 299 | X9: =Assumptions!$B$76+MAX(0,C9-Assumptions!$C$76)*Assumptions!$D$76 -> 990 | Y9: {=INDEX(Assumptions!$A$72:$A$76,MATCH(G9,T9:X9,0))} -> Starter
A10: 3 | B10: =A10*Assumptions!$B$11 -> 447 | C10: =A10*Assumptions!$B$13*Assumptions!$B$30+Assumptions!$B$59 -> 195 | D10: =C10/Assumptions!$B$15 -> 97.5 | E10: =(A10*Assumptions!$B$14+Assumptions!$B$60)*Assumptions!$B$42 -> 4.6 | F10: =C10*Assumptions!$B$41 -> 1.6575 | G10: =MIN(T10:X10) -> 15.6 | H10: =C10*((Assumptions!$B$47*Assumptions!$B$45/1000000)+(Assumptions!$B$48*Assumptions!$B$46/1000000)) -> 0 | I10: =D10*Assumptions!$B$52+D10*Assumptions!$B$33*Assumptions!$B$53 -> 0 | J10: =MAX(0,I10-Assumptions!$B$50)*Assumptions!$B$51 -> 0 | K10: =B10*Assumptions!$B$61 -> 0 | L10: =A10*(Assumptions!$B$55+Assumptions!$B$57) -> 0 | M10: =A10*Assumptions!$B$16*Assumptions!$B$31*Assumptions!$B$38 -> 75 | N10: =A10*Assumptions!$B$17*Assumptions!$B$32*Assumptions!$B$39 -> 0 | O10: ='Fixed Operating Costs'!$G$20 -> 49.99 | P10: =B10-SUM(E10:H10,J10:M10,O10) -> 300.1525 | Q10: =P10-N10 -> 300.1525 | R10: =P10/B10 -> 0.6714821 | S10: =(A10*Assumptions!$B$16*Assumptions!$B$31)/Assumptions!$B$40 -> 0.025 | T10: =Assumptions!$B$72+MAX(0,C10-Assumptions!$C$72)*Assumptions!$D$72 -> 15.6 | U10: =Assumptions!$B$73+MAX(0,C10-Assumptions!$C$73)*Assumptions!$D$73 -> 22 | V10: =Assumptions!$B$74+MAX(0,C10-Assumptions!$C$74)*Assumptions!$D$74 -> 99 | W10: =Assumptions!$B$75+MAX(0,C10-Assumptions!$C$75)*Assumptions!$D$75 -> 299 | X10: =Assumptions!$B$76+MAX(0,C10-Assumptions!$C$76)*Assumptions!$D$76 -> 990 | Y10: {=INDEX(Assumptions!$A$72:$A$76,MATCH(G10,T10:X10,0))} -> Starter
A11: 5 | B11: =A11*Assumptions!$B$11 -> 745 | C11: =A11*Assumptions!$B$13*Assumptions!$B$30+Assumptions!$B$59 -> 325 | D11: =C11/Assumptions!$B$15 -> 162.5 | E11: =(A11*Assumptions!$B$14+Assumptions!$B$60)*Assumptions!$B$42 -> 6.9 | F11: =C11*Assumptions!$B$41 -> 2.7625 | G11: =MIN(T11:X11) -> 26 | H11: =C11*((Assumptions!$B$47*Assumptions!$B$45/1000000)+(Assumptions!$B$48*Assumptions!$B$46/1000000)) -> 0 | I11: =D11*Assumptions!$B$52+D11*Assumptions!$B$33*Assumptions!$B$53 -> 0 | J11: =MAX(0,I11-Assumptions!$B$50)*Assumptions!$B$51 -> 0 | K11: =B11*Assumptions!$B$61 -> 0 | L11: =A11*(Assumptions!$B$55+Assumptions!$B$57) -> 0 | M11: =A11*Assumptions!$B$16*Assumptions!$B$31*Assumptions!$B$38 -> 125 | N11: =A11*Assumptions!$B$17*Assumptions!$B$32*Assumptions!$B$39 -> 0 | O11: ='Fixed Operating Costs'!$G$20 -> 49.99 | P11: =B11-SUM(E11:H11,J11:M11,O11) -> 534.3475 | Q11: =P11-N11 -> 534.3475 | R11: =P11/B11 -> 0.71724497 | S11: =(A11*Assumptions!$B$16*Assumptions!$B$31)/Assumptions!$B$40 -> 0.041666667 | T11: =Assumptions!$B$72+MAX(0,C11-Assumptions!$C$72)*Assumptions!$D$72 -> 26 | U11: =Assumptions!$B$73+MAX(0,C11-Assumptions!$C$73)*Assumptions!$D$73 -> 26 | V11: =Assumptions!$B$74+MAX(0,C11-Assumptions!$C$74)*Assumptions!$D$74 -> 99 | W11: =Assumptions!$B$75+MAX(0,C11-Assumptions!$C$75)*Assumptions!$D$75 -> 299 | X11: =Assumptions!$B$76+MAX(0,C11-Assumptions!$C$76)*Assumptions!$D$76 -> 990 | Y11: {=INDEX(Assumptions!$A$72:$A$76,MATCH(G11,T11:X11,0))} -> Starter
A12: 10 | B12: =A12*Assumptions!$B$11 -> 1490 | C12: =A12*Assumptions!$B$13*Assumptions!$B$30+Assumptions!$B$59 -> 650 | D12: =C12/Assumptions!$B$15 -> 325 | E12: =(A12*Assumptions!$B$14+Assumptions!$B$60)*Assumptions!$B$42 -> 12.65 | F12: =C12*Assumptions!$B$41 -> 5.525 | G12: =MIN(T12:X12) -> 52 | H12: =C12*((Assumptions!$B$47*Assumptions!$B$45/1000000)+(Assumptions!$B$48*Assumptions!$B$46/1000000)) -> 0 | I12: =D12*Assumptions!$B$52+D12*Assumptions!$B$33*Assumptions!$B$53 -> 0 | J12: =MAX(0,I12-Assumptions!$B$50)*Assumptions!$B$51 -> 0 | K12: =B12*Assumptions!$B$61 -> 0 | L12: =A12*(Assumptions!$B$55+Assumptions!$B$57) -> 0 | M12: =A12*Assumptions!$B$16*Assumptions!$B$31*Assumptions!$B$38 -> 250 | N12: =A12*Assumptions!$B$17*Assumptions!$B$32*Assumptions!$B$39 -> 0 | O12: ='Fixed Operating Costs'!$G$20 -> 49.99 | P12: =B12-SUM(E12:H12,J12:M12,O12) -> 1119.835 | Q12: =P12-N12 -> 1119.835 | R12: =P12/B12 -> 0.75156711 | S12: =(A12*Assumptions!$B$16*Assumptions!$B$31)/Assumptions!$B$40 -> 0.083333333 | T12: =Assumptions!$B$72+MAX(0,C12-Assumptions!$C$72)*Assumptions!$D$72 -> 52 | U12: =Assumptions!$B$73+MAX(0,C12-Assumptions!$C$73)*Assumptions!$D$73 -> 52 | V12: =Assumptions!$B$74+MAX(0,C12-Assumptions!$C$74)*Assumptions!$D$74 -> 99 | W12: =Assumptions!$B$75+MAX(0,C12-Assumptions!$C$75)*Assumptions!$D$75 -> 299 | X12: =Assumptions!$B$76+MAX(0,C12-Assumptions!$C$76)*Assumptions!$D$76 -> 990 | Y12: {=INDEX(Assumptions!$A$72:$A$76,MATCH(G12,T12:X12,0))} -> Starter
A13: 15 | B13: =A13*Assumptions!$B$11 -> 2235 | C13: =A13*Assumptions!$B$13*Assumptions!$B$30+Assumptions!$B$59 -> 975 | D13: =C13/Assumptions!$B$15 -> 487.5 | E13: =(A13*Assumptions!$B$14+Assumptions!$B$60)*Assumptions!$B$42 -> 18.4 | F13: =C13*Assumptions!$B$41 -> 8.2875 | G13: =MIN(T13:X13) -> 78 | H13: =C13*((Assumptions!$B$47*Assumptions!$B$45/1000000)+(Assumptions!$B$48*Assumptions!$B$46/1000000)) -> 0 | I13: =D13*Assumptions!$B$52+D13*Assumptions!$B$33*Assumptions!$B$53 -> 0 | J13: =MAX(0,I13-Assumptions!$B$50)*Assumptions!$B$51 -> 0 | K13: =B13*Assumptions!$B$61 -> 0 | L13: =A13*(Assumptions!$B$55+Assumptions!$B$57) -> 0 | M13: =A13*Assumptions!$B$16*Assumptions!$B$31*Assumptions!$B$38 -> 375 | N13: =A13*Assumptions!$B$17*Assumptions!$B$32*Assumptions!$B$39 -> 0 | O13: ='Fixed Operating Costs'!$G$20 -> 49.99 | P13: =B13-SUM(E13:H13,J13:M13,O13) -> 1705.3225 | Q13: =P13-N13 -> 1705.3225 | R13: =P13/B13 -> 0.76300783 | S13: =(A13*Assumptions!$B$16*Assumptions!$B$31)/Assumptions!$B$40 -> 0.125 | T13: =Assumptions!$B$72+MAX(0,C13-Assumptions!$C$72)*Assumptions!$D$72 -> 78 | U13: =Assumptions!$B$73+MAX(0,C13-Assumptions!$C$73)*Assumptions!$D$73 -> 78 | V13: =Assumptions!$B$74+MAX(0,C13-Assumptions!$C$74)*Assumptions!$D$74 -> 99 | W13: =Assumptions!$B$75+MAX(0,C13-Assumptions!$C$75)*Assumptions!$D$75 -> 299 | X13: =Assumptions!$B$76+MAX(0,C13-Assumptions!$C$76)*Assumptions!$D$76 -> 990 | Y13: {=INDEX(Assumptions!$A$72:$A$76,MATCH(G13,T13:X13,0))} -> Starter
A14: 20 | B14: =A14*Assumptions!$B$11 -> 2980 | C14: =A14*Assumptions!$B$13*Assumptions!$B$30+Assumptions!$B$59 -> 1300 | D14: =C14/Assumptions!$B$15 -> 650 | E14: =(A14*Assumptions!$B$14+Assumptions!$B$60)*Assumptions!$B$42 -> 24.15 | F14: =C14*Assumptions!$B$41 -> 11.05 | G14: =MIN(T14:X14) -> 103.96 | H14: =C14*((Assumptions!$B$47*Assumptions!$B$45/1000000)+(Assumptions!$B$48*Assumptions!$B$46/1000000)) -> 0 | I14: =D14*Assumptions!$B$52+D14*Assumptions!$B$33*Assumptions!$B$53 -> 0 | J14: =MAX(0,I14-Assumptions!$B$50)*Assumptions!$B$51 -> 0 | K14: =B14*Assumptions!$B$61 -> 0 | L14: =A14*(Assumptions!$B$55+Assumptions!$B$57) -> 0 | M14: =A14*Assumptions!$B$16*Assumptions!$B$31*Assumptions!$B$38 -> 500 | N14: =A14*Assumptions!$B$17*Assumptions!$B$32*Assumptions!$B$39 -> 0 | O14: ='Fixed Operating Costs'!$G$20 -> 49.99 | P14: =B14-SUM(E14:H14,J14:M14,O14) -> 2290.85 | Q14: =P14-N14 -> 2290.85 | R14: =P14/B14 -> 0.76874161 | S14: =(A14*Assumptions!$B$16*Assumptions!$B$31)/Assumptions!$B$40 -> 0.16666667 | T14: =Assumptions!$B$72+MAX(0,C14-Assumptions!$C$72)*Assumptions!$D$72 -> 104 | U14: =Assumptions!$B$73+MAX(0,C14-Assumptions!$C$73)*Assumptions!$D$73 -> 104 | V14: =Assumptions!$B$74+MAX(0,C14-Assumptions!$C$74)*Assumptions!$D$74 -> 103.96 | W14: =Assumptions!$B$75+MAX(0,C14-Assumptions!$C$75)*Assumptions!$D$75 -> 299 | X14: =Assumptions!$B$76+MAX(0,C14-Assumptions!$C$76)*Assumptions!$D$76 -> 990 | Y14: {=INDEX(Assumptions!$A$72:$A$76,MATCH(G14,T14:X14,0))} -> Pro
A15: 30 | B15: =A15*Assumptions!$B$11 -> 4470 | C15: =A15*Assumptions!$B$13*Assumptions!$B$30+Assumptions!$B$59 -> 1950 | D15: =C15/Assumptions!$B$15 -> 975 | E15: =(A15*Assumptions!$B$14+Assumptions!$B$60)*Assumptions!$B$42 -> 35.65 | F15: =C15*Assumptions!$B$41 -> 16.575 | G15: =MIN(T15:X15) -> 155.96 | H15: =C15*((Assumptions!$B$47*Assumptions!$B$45/1000000)+(Assumptions!$B$48*Assumptions!$B$46/1000000)) -> 0 | I15: =D15*Assumptions!$B$52+D15*Assumptions!$B$33*Assumptions!$B$53 -> 0 | J15: =MAX(0,I15-Assumptions!$B$50)*Assumptions!$B$51 -> 0 | K15: =B15*Assumptions!$B$61 -> 0 | L15: =A15*(Assumptions!$B$55+Assumptions!$B$57) -> 0 | M15: =A15*Assumptions!$B$16*Assumptions!$B$31*Assumptions!$B$38 -> 750 | N15: =A15*Assumptions!$B$17*Assumptions!$B$32*Assumptions!$B$39 -> 0 | O15: ='Fixed Operating Costs'!$G$20 -> 49.99 | P15: =B15-SUM(E15:H15,J15:M15,O15) -> 3461.825 | Q15: =P15-N15 -> 3461.825 | R15: =P15/B15 -> 0.77445749 | S15: =(A15*Assumptions!$B$16*Assumptions!$B$31)/Assumptions!$B$40 -> 0.25 | T15: =Assumptions!$B$72+MAX(0,C15-Assumptions!$C$72)*Assumptions!$D$72 -> 156 | U15: =Assumptions!$B$73+MAX(0,C15-Assumptions!$C$73)*Assumptions!$D$73 -> 156 | V15: =Assumptions!$B$74+MAX(0,C15-Assumptions!$C$74)*Assumptions!$D$74 -> 155.96 | W15: =Assumptions!$B$75+MAX(0,C15-Assumptions!$C$75)*Assumptions!$D$75 -> 299 | X15: =Assumptions!$B$76+MAX(0,C15-Assumptions!$C$76)*Assumptions!$D$76 -> 990 | Y15: {=INDEX(Assumptions!$A$72:$A$76,MATCH(G15,T15:X15,0))} -> Pro
A16: 50 | B16: =A16*Assumptions!$B$11 -> 7450 | C16: =A16*Assumptions!$B$13*Assumptions!$B$30+Assumptions!$B$59 -> 3250 | D16: =C16/Assumptions!$B$15 -> 1625 | E16: =(A16*Assumptions!$B$14+Assumptions!$B$60)*Assumptions!$B$42 -> 58.65 | F16: =C16*Assumptions!$B$41 -> 27.625 | G16: =MIN(T16:X16) -> 259.96 | H16: =C16*((Assumptions!$B$47*Assumptions!$B$45/1000000)+(Assumptions!$B$48*Assumptions!$B$46/1000000)) -> 0 | I16: =D16*Assumptions!$B$52+D16*Assumptions!$B$33*Assumptions!$B$53 -> 0 | J16: =MAX(0,I16-Assumptions!$B$50)*Assumptions!$B$51 -> 0 | K16: =B16*Assumptions!$B$61 -> 0 | L16: =A16*(Assumptions!$B$55+Assumptions!$B$57) -> 0 | M16: =A16*Assumptions!$B$16*Assumptions!$B$31*Assumptions!$B$38 -> 1250 | N16: =A16*Assumptions!$B$17*Assumptions!$B$32*Assumptions!$B$39 -> 0 | O16: ='Fixed Operating Costs'!$G$20 -> 49.99 | P16: =B16-SUM(E16:H16,J16:M16,O16) -> 5803.775 | Q16: =P16-N16 -> 5803.775 | R16: =P16/B16 -> 0.7790302 | S16: =(A16*Assumptions!$B$16*Assumptions!$B$31)/Assumptions!$B$40 -> 0.41666667 | T16: =Assumptions!$B$72+MAX(0,C16-Assumptions!$C$72)*Assumptions!$D$72 -> 260 | U16: =Assumptions!$B$73+MAX(0,C16-Assumptions!$C$73)*Assumptions!$D$73 -> 260 | V16: =Assumptions!$B$74+MAX(0,C16-Assumptions!$C$74)*Assumptions!$D$74 -> 259.96 | W16: =Assumptions!$B$75+MAX(0,C16-Assumptions!$C$75)*Assumptions!$D$75 -> 299 | X16: =Assumptions!$B$76+MAX(0,C16-Assumptions!$C$76)*Assumptions!$D$76 -> 990 | Y16: {=INDEX(Assumptions!$A$72:$A$76,MATCH(G16,T16:X16,0))} -> Pro
A17: 100 | B17: =A17*Assumptions!$B$11 -> 14900 | C17: =A17*Assumptions!$B$13*Assumptions!$B$30+Assumptions!$B$59 -> 6500 | D17: =C17/Assumptions!$B$15 -> 3250 | E17: =(A17*Assumptions!$B$14+Assumptions!$B$60)*Assumptions!$B$42 -> 116.15 | F17: =C17*Assumptions!$B$41 -> 55.25 | G17: =MIN(T17:X17) -> 519.96 | H17: =C17*((Assumptions!$B$47*Assumptions!$B$45/1000000)+(Assumptions!$B$48*Assumptions!$B$46/1000000)) -> 0 | I17: =D17*Assumptions!$B$52+D17*Assumptions!$B$33*Assumptions!$B$53 -> 0 | J17: =MAX(0,I17-Assumptions!$B$50)*Assumptions!$B$51 -> 0 | K17: =B17*Assumptions!$B$61 -> 0 | L17: =A17*(Assumptions!$B$55+Assumptions!$B$57) -> 0 | M17: =A17*Assumptions!$B$16*Assumptions!$B$31*Assumptions!$B$38 -> 2500 | N17: =A17*Assumptions!$B$17*Assumptions!$B$32*Assumptions!$B$39 -> 0 | O17: ='Fixed Operating Costs'!$G$20 -> 49.99 | P17: =B17-SUM(E17:H17,J17:M17,O17) -> 11658.65 | Q17: =P17-N17 -> 11658.65 | R17: =P17/B17 -> 0.78245973 | S17: =(A17*Assumptions!$B$16*Assumptions!$B$31)/Assumptions!$B$40 -> 0.83333333 | T17: =Assumptions!$B$72+MAX(0,C17-Assumptions!$C$72)*Assumptions!$D$72 -> 520 | U17: =Assumptions!$B$73+MAX(0,C17-Assumptions!$C$73)*Assumptions!$D$73 -> 520 | V17: =Assumptions!$B$74+MAX(0,C17-Assumptions!$C$74)*Assumptions!$D$74 -> 519.96 | W17: =Assumptions!$B$75+MAX(0,C17-Assumptions!$C$75)*Assumptions!$D$75 -> 519.96 | X17: =Assumptions!$B$76+MAX(0,C17-Assumptions!$C$76)*Assumptions!$D$76 -> 990 | Y17: {=INDEX(Assumptions!$A$72:$A$76,MATCH(G17,T17:X17,0))} -> Pro

Sheet Margins & Unit Economics
A1: Margins & Unit Economics
A2: Decision view of plan economics. Cash margin excludes owner opportunity cost until Assumptions B39 is populated.
A4: PLAN MARGINS & BREAK-EVEN
A5: Plan | B5: Price | C5: Scenario minutes | D5: Known cash cost | E5: Cash contribution | F5: Cash margin | G5: Fully loaded contribution | H5: Fully loaded margin | I5: Dev hours used | J5: Revenue / dev hour | K5: Selected-case break-even clients | L5: First-client cash profit after fixed
A6: Starter | B6: ='Per-Customer Costs'!B6 -> 149 | C6: ='Per-Customer Costs'!D6 -> 65 | D6: ='Per-Customer Costs'!O6 -> 31.9025 | E6: =B6-D6 -> 117.0975 | F6: =E6/B6 -> 0.78588926 | G6: ='Per-Customer Costs'!Q6 -> 117.0975 | H6: =G6/B6 -> 0.78588926 | I6: =Assumptions!$B$16*Assumptions!$B$31 -> 1 | J6: =IF(I6=0,0,B6/I6) -> 149 | K6: =ROUNDUP('Fixed Operating Costs'!$G$20/MAX(1,E6),0) -> 1 | L6: =Assumptions!$B$11-((Assumptions!$B$14+Assumptions!$B$60)*Assumptions!$B$42)-((Assumptions!$B$13*Assumptions!$B$30+Assumptions!$B$59)*Assumptions!$B$41)-(MIN(Assumptions!$B$72+MAX(0,(Assumptions!$B$13*Assumptions!$B$30+Assumptions!$B$59)-Assumptions!$C$72)*Assumptions!$D$72,Assumptions!$B$73+MAX(0,(Assumptions!$B$13*Assumptions!$B$30+Assumptions!$B$59)-Assumptions!$C$73)*Assumptions!$D$73,Assumptions!$B$74+MAX(0,(Assumptions!$B$13*Assumptions!$B$30+Assumptions!$B$59)-Assumptions!$C$74)*Assumptions!$D$74,Assumptions!$B$75+MAX(0,(Assumptions!$B$13*Assumptions!$B$30+Assumptions!$B$59)-Assumptions!$C$75)*Assumptions!$D$75,Assumptions!$B$76+MAX(0,(Assumptions!$B$13*Assumptions!$B$30+Assumptions!$B$59)-Assumptions!$C$76)*Assumptions!$D$76))-((Assumptions!$B$13*Assumptions!$B$30+Assumptions!$B$59)*( (Assumptions!$B$47*Assumptions!$B$45/1000000)+(Assumptions!$B$48*Assumptions!$B$46/1000000) ))-(MAX(0,(((Assumptions!$B$13*Assumptions!$B$30+Assumptions!$B$59)/Assumptions!$B$15)*Assumptions!$B$52+((Assumptions!$B$13*Assumptions!$B$30+Assumptions!$B$59)/Assumptions!$B$15)*Assumptions!$B$33*Assumptions!$B$53)-Assumptions!$B$50)*Assumptions!$B$51)-(Assumptions!$B$11*Assumptions!$B$61)-Assumptions!$B$55-Assumptions!$B$57-(Assumptions!$B$16*Assumptions!$B$31*Assumptions!$B$38)-'Fixed Operating Costs'!$G$20 -> 65.1575
A7: Growth | B7: ='Per-Customer Costs'!B7 -> 199 | C7: ='Per-Customer Costs'!D7 -> 162.5 | D7: ='Per-Customer Costs'!O7 -> 65.53125 | E7: =B7-D7 -> 133.46875 | F7: =E7/B7 -> 0.67069724 | G7: ='Per-Customer Costs'!Q7 -> 133.46875 | H7: =G7/B7 -> 0.67069724 | I7: =Assumptions!$C$16*Assumptions!$B$31 -> 2 | J7: =IF(I7=0,0,B7/I7) -> 99.5 | K7: =ROUNDUP('Fixed Operating Costs'!$G$20/MAX(1,E7),0) -> 1 | L7: =Assumptions!$C$11-((Assumptions!$C$14+Assumptions!$B$60)*Assumptions!$B$42)-((Assumptions!$C$13*Assumptions!$B$30+Assumptions!$B$59)*Assumptions!$B$41)-(MIN(Assumptions!$B$72+MAX(0,(Assumptions!$C$13*Assumptions!$B$30+Assumptions!$B$59)-Assumptions!$C$72)*Assumptions!$D$72,Assumptions!$B$73+MAX(0,(Assumptions!$C$13*Assumptions!$B$30+Assumptions!$B$59)-Assumptions!$C$73)*Assumptions!$D$73,Assumptions!$B$74+MAX(0,(Assumptions!$C$13*Assumptions!$B$30+Assumptions!$B$59)-Assumptions!$C$74)*Assumptions!$D$74,Assumptions!$B$75+MAX(0,(Assumptions!$C$13*Assumptions!$B$30+Assumptions!$B$59)-Assumptions!$C$75)*Assumptions!$D$75,Assumptions!$B$76+MAX(0,(Assumptions!$C$13*Assumptions!$B$30+Assumptions!$B$59)-Assumptions!$C$76)*Assumptions!$D$76))-((Assumptions!$C$13*Assumptions!$B$30+Assumptions!$B$59)*( (Assumptions!$B$47*Assumptions!$B$45/1000000)+(Assumptions!$B$48*Assumptions!$B$46/1000000) ))-(MAX(0,(((Assumptions!$C$13*Assumptions!$B$30+Assumptions!$B$59)/Assumptions!$C$15)*Assumptions!$B$52+((Assumptions!$C$13*Assumptions!$B$30+Assumptions!$B$59)/Assumptions!$C$15)*Assumptions!$B$33*Assumptions!$B$53)-Assumptions!$B$50)*Assumptions!$B$51)-(Assumptions!$C$11*Assumptions!$B$61)-Assumptions!$B$55-Assumptions!$B$57-(Assumptions!$C$16*Assumptions!$B$31*Assumptions!$B$38)-'Fixed Operating Costs'!$G$20 -> 82.32875
A8: Scale | B8: ='Per-Customer Costs'!B8 -> 349 | C8: ='Per-Customer Costs'!D8 -> 390 | D8: ='Per-Customer Costs'!O8 -> 136.815 | E8: =B8-D8 -> 212.185 | F8: =E8/B8 -> 0.60797994 | G8: ='Per-Customer Costs'!Q8 -> 212.185 | H8: =G8/B8 -> 0.60797994 | I8: =Assumptions!$D$16*Assumptions!$B$31 -> 4 | J8: =IF(I8=0,0,B8/I8) -> 87.25 | K8: =ROUNDUP('Fixed Operating Costs'!$G$20/MAX(1,E8),0) -> 1 | L8: =Assumptions!$D$11-((Assumptions!$D$14+Assumptions!$B$60)*Assumptions!$B$42)-((Assumptions!$D$13*Assumptions!$B$30+Assumptions!$B$59)*Assumptions!$B$41)-(MIN(Assumptions!$B$72+MAX(0,(Assumptions!$D$13*Assumptions!$B$30+Assumptions!$B$59)-Assumptions!$C$72)*Assumptions!$D$72,Assumptions!$B$73+MAX(0,(Assumptions!$D$13*Assumptions!$B$30+Assumptions!$B$59)-Assumptions!$C$73)*Assumptions!$D$73,Assumptions!$B$74+MAX(0,(Assumptions!$D$13*Assumptions!$B$30+Assumptions!$B$59)-Assumptions!$C$74)*Assumptions!$D$74,Assumptions!$B$75+MAX(0,(Assumptions!$D$13*Assumptions!$B$30+Assumptions!$B$59)-Assumptions!$C$75)*Assumptions!$D$75,Assumptions!$B$76+MAX(0,(Assumptions!$D$13*Assumptions!$B$30+Assumptions!$B$59)-Assumptions!$C$76)*Assumptions!$D$76))-((Assumptions!$D$13*Assumptions!$B$30+Assumptions!$B$59)*( (Assumptions!$B$47*Assumptions!$B$45/1000000)+(Assumptions!$B$48*Assumptions!$B$46/1000000) ))-(MAX(0,(((Assumptions!$D$13*Assumptions!$B$30+Assumptions!$B$59)/Assumptions!$D$15)*Assumptions!$B$52+((Assumptions!$D$13*Assumptions!$B$30+Assumptions!$B$59)/Assumptions!$D$15)*Assumptions!$B$33*Assumptions!$B$53)-Assumptions!$B$50)*Assumptions!$B$51)-(Assumptions!$D$11*Assumptions!$B$61)-Assumptions!$B$55-Assumptions!$B$57-(Assumptions!$D$16*Assumptions!$B$31*Assumptions!$B$38)-'Fixed Operating Costs'!$G$20 -> 161.045
A12: ONE STARTER CLIENT — COST BRIDGE
A13: Revenue | B13: Fixed opex | C13: Phone numbers | D13: Twilio | E13: ElevenLabs | F13: Developer | G13: Other known variable | H13: Cash profit
A14: ='Profitability Forecast'!B8 -> 149 | B14: ='Profitability Forecast'!O8 -> 49.99 | C14: ='Profitability Forecast'!E8 -> 2.3 | D14: ='Profitability Forecast'!F8 -> 0.5525 | E14: ='Profitability Forecast'!G8 -> 6 | F14: ='Profitability Forecast'!M8 -> 25 | G14: =SUM('Profitability Forecast'!H8,'Profitability Forecast'!J8:L8) -> 0 | H14: ='Profitability Forecast'!P8 -> 65.1575

Sheet KPIs
A1: KPIs
A2: Operational scorecard at the client count selected in Assumptions. KPI gaps stay explicit until sales and usage telemetry exist.
A4: SELECTED-SCALE KPI SCORECARD
A5: KPI | B5: Value | C5: Unit | D5: Interpretation | E5: KPI | F5: Value | G5: Unit | H5: Interpretation
A6: Clients | B6: =Assumptions!$E$5 -> 10 | C6: accounts | D6: Selected planning point | E6: MRR | F6: {=INDEX('Profitability Forecast'!$B$8:$B$17,MATCH(B6,'Profitability Forecast'!$A$8:$A$17,0))} -> 1490 | G6: $ / month | H6: Recurring revenue
A7: ARR | B7: =F6*12 -> 17880 | C7: $ / year | D7: MRR × 12 | E7: ARPA | F7: =F6/B6 -> 149 | G7: $ / client | H7: Starter-only forecast
A8: Cash operating profit | B8: {=INDEX('Profitability Forecast'!$P$8:$P$17,MATCH(B6,'Profitability Forecast'!$A$8:$A$17,0))} -> 1119.835 | C8: $ / month | D8: Before owner opportunity cost | E8: Cash net margin | F8: {=INDEX('Profitability Forecast'!$R$8:$R$17,MATCH(B6,'Profitability Forecast'!$A$8:$A$17,0))} -> 0.75156711 | G8: % | H8: After fixed overhead
A9: Handled minutes | B9: {=INDEX('Profitability Forecast'!$C$8:$C$17,MATCH(B6,'Profitability Forecast'!$A$8:$A$17,0))} -> 650 | C9: minutes / month | D9: Includes public demo use | E9: Cost per handled minute | F9: =IF(B9=0,0,(F6-B8)/B9) -> 0.56948462 | G9: $ / minute | H9: All known cash costs / minutes
A10: Developer FTE required | B10: {=INDEX('Profitability Forecast'!$S$8:$S$17,MATCH(B6,'Profitability Forecast'!$A$8:$A$17,0))} -> 0.083333333 | C10: FTE | D10: Based on productive hours input | E10: Revenue per dev hour | F10: =IF(B10=0,0,F6/(B10*Assumptions!$B$40)) -> 149 | G10: $ / hour | H10: Measures service leverage
A11: Break-even clients | B11: ='Margins & Unit Economics'!$K$6 -> 1 | C11: clients | D11: Selected-scenario unit contribution | E11: Fixed-cost coverage | F11: =F6/'Fixed Operating Costs'!$G$20 -> 29.805961 | G11: x | H11: Revenue / fixed opex
A12: CAC payback | B12: =IF(Assumptions!$B$62=0,0,Assumptions!$B$62/'Margins & Unit Economics'!$E$6) -> 0 | C12: months | D12: Requires CAC | E12: Indicative LTV | F12: =IF(Assumptions!$B$63=0,0,'Margins & Unit Economics'!$E$6/Assumptions!$B$63) -> 0 | G12: $ | H12: Requires churn and ARPA contribution
A16: KPI DEFINITIONS & MANAGEMENT CADENCE
A17: KPI | B17: Definition | C17: Target / trigger | D17: Cadence | E17: Owner | F17: Current limitation
A18: Cash margin | B18: Revenue less known cash costs and fixed opex ÷ revenue | C18: Positive from client 1; protect ≥60% at scale | D18: Monthly | E18: CEO/CFO | F18: Unknown token/task/owner costs can reduce it
A19: Developer utilization | B19: Client care hours ÷ productive capacity | C19: Hire/contract before sustained 80% | D19: Weekly | E19: Developer | F19: Use actual time tracking
A20: Call containment | B20: Calls completed without human callback | C20: Set after first 100 calls | D20: Weekly | E20: Product | F20: No production telemetry
A21: Ticket rate | B21: Unresolved-call tickets ÷ calls | C21: Downward trend without quality loss | D21: Weekly | E21: Client success | F21: Scenario input only
A22: CAC payback | B22: CAC ÷ monthly cash contribution | C22: <6 months at launch | D22: Monthly | E22: CEO | F22: CAC input required
A23: Logo churn | B23: Lost clients ÷ opening clients | C23: <2% monthly when scaled | D23: Monthly | E23: CEO | F23: No retention history

Sheet Scenario Analysis
A1: Scenario Analysis
A2: Side-by-side stress test for Starter clients at the selected client count. Unknown usage inputs remain visible and formula-linked.
A4: Selected clients | B4: =Assumptions!$E$5 -> 10
A6: SCENARIO COMPARISON | F6: ONE-CLIENT STARTER PRICE SENSITIVITY — CASH PROFIT
A7: Metric | B7: Conservative | C7: Expected | D7: Efficient | F7: Monthly price | G7: 0.4 | H7: 0.65 | I7: 1
A8: Minute utilization | B8: =Assumptions!$B$25 -> 1 | C8: =Assumptions!$B$26 -> 0.65 | D8: =Assumptions!$B$27 -> 0.4 | F8: 129 | G8: =$F8-'Fixed Operating Costs'!$G$20-(Assumptions!$B$14+Assumptions!$B$60)*Assumptions!$B$42-(Assumptions!$B$13*$G$7+Assumptions!$B$59)*Assumptions!$B$41-MIN(Assumptions!$B$72+MAX(0,(Assumptions!$B$13*$G$7+Assumptions!$B$59)-Assumptions!$C$72)*Assumptions!$D$72,Assumptions!$B$73+MAX(0,(Assumptions!$B$13*$G$7+Assumptions!$B$59)-Assumptions!$C$73)*Assumptions!$D$73,Assumptions!$B$74+MAX(0,(Assumptions!$B$13*$G$7+Assumptions!$B$59)-Assumptions!$C$74)*Assumptions!$D$74)-(Assumptions!$B$13*$G$7+Assumptions!$B$59)*((Assumptions!$B$47*Assumptions!$B$45/1000000)+(Assumptions!$B$48*Assumptions!$B$46/1000000))-MAX(0,(((Assumptions!$B$13*$G$7+Assumptions!$B$59)/Assumptions!$B$15)*Assumptions!$B$52+((Assumptions!$B$13*$G$7+Assumptions!$B$59)/Assumptions!$B$15)*Assumptions!$B$33*Assumptions!$B$53)-Assumptions!$B$50)*Assumptions!$B$51-$F8*Assumptions!$B$61-(Assumptions!$B$55+Assumptions!$B$57)-Assumptions!$B$16*$G$7*Assumptions!$B$38 -> 50.37 | H8: =$F8-'Fixed Operating Costs'!$G$20-(Assumptions!$B$14+Assumptions!$B$60)*Assumptions!$B$42-(Assumptions!$B$13*$H$7+Assumptions!$B$59)*Assumptions!$B$41-MIN(Assumptions!$B$72+MAX(0,(Assumptions!$B$13*$H$7+Assumptions!$B$59)-Assumptions!$C$72)*Assumptions!$D$72,Assumptions!$B$73+MAX(0,(Assumptions!$B$13*$H$7+Assumptions!$B$59)-Assumptions!$C$73)*Assumptions!$D$73,Assumptions!$B$74+MAX(0,(Assumptions!$B$13*$H$7+Assumptions!$B$59)-Assumptions!$C$74)*Assumptions!$D$74)-(Assumptions!$B$13*$H$7+Assumptions!$B$59)*((Assumptions!$B$47*Assumptions!$B$45/1000000)+(Assumptions!$B$48*Assumptions!$B$46/1000000))-MAX(0,(((Assumptions!$B$13*$H$7+Assumptions!$B$59)/Assumptions!$B$15)*Assumptions!$B$52+((Assumptions!$B$13*$H$7+Assumptions!$B$59)/Assumptions!$B$15)*Assumptions!$B$33*Assumptions!$B$53)-Assumptions!$B$50)*Assumptions!$B$51-$F8*Assumptions!$B$61-(Assumptions!$B$55+Assumptions!$B$57)-Assumptions!$B$16*$H$7*Assumptions!$B$38 -> 37.6575 | I8: =$F8-'Fixed Operating Costs'!$G$20-(Assumptions!$B$14+Assumptions!$B$60)*Assumptions!$B$42-(Assumptions!$B$13*$I$7+Assumptions!$B$59)*Assumptions!$B$41-MIN(Assumptions!$B$72+MAX(0,(Assumptions!$B$13*$I$7+Assumptions!$B$59)-Assumptions!$C$72)*Assumptions!$D$72,Assumptions!$B$73+MAX(0,(Assumptions!$B$13*$I$7+Assumptions!$B$59)-Assumptions!$C$73)*Assumptions!$D$73,Assumptions!$B$74+MAX(0,(Assumptions!$B$13*$I$7+Assumptions!$B$59)-Assumptions!$C$74)*Assumptions!$D$74)-(Assumptions!$B$13*$I$7+Assumptions!$B$59)*((Assumptions!$B$47*Assumptions!$B$45/1000000)+(Assumptions!$B$48*Assumptions!$B$46/1000000))-MAX(0,(((Assumptions!$B$13*$I$7+Assumptions!$B$59)/Assumptions!$B$15)*Assumptions!$B$52+((Assumptions!$B$13*$I$7+Assumptions!$B$59)/Assumptions!$B$15)*Assumptions!$B$33*Assumptions!$B$53)-Assumptions!$B$50)*Assumptions!$B$51-$F8*Assumptions!$B$61-(Assumptions!$B$55+Assumptions!$B$57)-Assumptions!$B$16*$I$7*Assumptions!$B$38 -> 17.86
A9: Developer utilization | B9: =Assumptions!$C$25 -> 1 | C9: =Assumptions!$C$26 -> 0.5 | D9: =Assumptions!$C$27 -> 0.25 | F9: 149 | G9: =$F9-'Fixed Operating Costs'!$G$20-(Assumptions!$B$14+Assumptions!$B$60)*Assumptions!$B$42-(Assumptions!$B$13*$G$7+Assumptions!$B$59)*Assumptions!$B$41-MIN(Assumptions!$B$72+MAX(0,(Assumptions!$B$13*$G$7+Assumptions!$B$59)-Assumptions!$C$72)*Assumptions!$D$72,Assumptions!$B$73+MAX(0,(Assumptions!$B$13*$G$7+Assumptions!$B$59)-Assumptions!$C$73)*Assumptions!$D$73,Assumptions!$B$74+MAX(0,(Assumptions!$B$13*$G$7+Assumptions!$B$59)-Assumptions!$C$74)*Assumptions!$D$74)-(Assumptions!$B$13*$G$7+Assumptions!$B$59)*((Assumptions!$B$47*Assumptions!$B$45/1000000)+(Assumptions!$B$48*Assumptions!$B$46/1000000))-MAX(0,(((Assumptions!$B$13*$G$7+Assumptions!$B$59)/Assumptions!$B$15)*Assumptions!$B$52+((Assumptions!$B$13*$G$7+Assumptions!$B$59)/Assumptions!$B$15)*Assumptions!$B$33*Assumptions!$B$53)-Assumptions!$B$50)*Assumptions!$B$51-$F9*Assumptions!$B$61-(Assumptions!$B$55+Assumptions!$B$57)-Assumptions!$B$16*$G$7*Assumptions!$B$38 -> 70.37 | H9: =$F9-'Fixed Operating Costs'!$G$20-(Assumptions!$B$14+Assumptions!$B$60)*Assumptions!$B$42-(Assumptions!$B$13*$H$7+Assumptions!$B$59)*Assumptions!$B$41-MIN(Assumptions!$B$72+MAX(0,(Assumptions!$B$13*$H$7+Assumptions!$B$59)-Assumptions!$C$72)*Assumptions!$D$72,Assumptions!$B$73+MAX(0,(Assumptions!$B$13*$H$7+Assumptions!$B$59)-Assumptions!$C$73)*Assumptions!$D$73,Assumptions!$B$74+MAX(0,(Assumptions!$B$13*$H$7+Assumptions!$B$59)-Assumptions!$C$74)*Assumptions!$D$74)-(Assumptions!$B$13*$H$7+Assumptions!$B$59)*((Assumptions!$B$47*Assumptions!$B$45/1000000)+(Assumptions!$B$48*Assumptions!$B$46/1000000))-MAX(0,(((Assumptions!$B$13*$H$7+Assumptions!$B$59)/Assumptions!$B$15)*Assumptions!$B$52+((Assumptions!$B$13*$H$7+Assumptions!$B$59)/Assumptions!$B$15)*Assumptions!$B$33*Assumptions!$B$53)-Assumptions!$B$50)*Assumptions!$B$51-$F9*Assumptions!$B$61-(Assumptions!$B$55+Assumptions!$B$57)-Assumptions!$B$16*$H$7*Assumptions!$B$38 -> 57.6575 | I9: =$F9-'Fixed Operating Costs'!$G$20-(Assumptions!$B$14+Assumptions!$B$60)*Assumptions!$B$42-(Assumptions!$B$13*$I$7+Assumptions!$B$59)*Assumptions!$B$41-MIN(Assumptions!$B$72+MAX(0,(Assumptions!$B$13*$I$7+Assumptions!$B$59)-Assumptions!$C$72)*Assumptions!$D$72,Assumptions!$B$73+MAX(0,(Assumptions!$B$13*$I$7+Assumptions!$B$59)-Assumptions!$C$73)*Assumptions!$D$73,Assumptions!$B$74+MAX(0,(Assumptions!$B$13*$I$7+Assumptions!$B$59)-Assumptions!$C$74)*Assumptions!$D$74)-(Assumptions!$B$13*$I$7+Assumptions!$B$59)*((Assumptions!$B$47*Assumptions!$B$45/1000000)+(Assumptions!$B$48*Assumptions!$B$46/1000000))-MAX(0,(((Assumptions!$B$13*$I$7+Assumptions!$B$59)/Assumptions!$B$15)*Assumptions!$B$52+((Assumptions!$B$13*$I$7+Assumptions!$B$59)/Assumptions!$B$15)*Assumptions!$B$33*Assumptions!$B$53)-Assumptions!$B$50)*Assumptions!$B$51-$F9*Assumptions!$B$61-(Assumptions!$B$55+Assumptions!$B$57)-Assumptions!$B$16*$I$7*Assumptions!$B$38 -> 37.86
A10: Owner utilization | B10: =Assumptions!$D$25 -> 1 | C10: =Assumptions!$D$26 -> 0.5 | D10: =Assumptions!$D$27 -> 0.25 | F10: 169 | G10: =$F10-'Fixed Operating Costs'!$G$20-(Assumptions!$B$14+Assumptions!$B$60)*Assumptions!$B$42-(Assumptions!$B$13*$G$7+Assumptions!$B$59)*Assumptions!$B$41-MIN(Assumptions!$B$72+MAX(0,(Assumptions!$B$13*$G$7+Assumptions!$B$59)-Assumptions!$C$72)*Assumptions!$D$72,Assumptions!$B$73+MAX(0,(Assumptions!$B$13*$G$7+Assumptions!$B$59)-Assumptions!$C$73)*Assumptions!$D$73,Assumptions!$B$74+MAX(0,(Assumptions!$B$13*$G$7+Assumptions!$B$59)-Assumptions!$C$74)*Assumptions!$D$74)-(Assumptions!$B$13*$G$7+Assumptions!$B$59)*((Assumptions!$B$47*Assumptions!$B$45/1000000)+(Assumptions!$B$48*Assumptions!$B$46/1000000))-MAX(0,(((Assumptions!$B$13*$G$7+Assumptions!$B$59)/Assumptions!$B$15)*Assumptions!$B$52+((Assumptions!$B$13*$G$7+Assumptions!$B$59)/Assumptions!$B$15)*Assumptions!$B$33*Assumptions!$B$53)-Assumptions!$B$50)*Assumptions!$B$51-$F10*Assumptions!$B$61-(Assumptions!$B$55+Assumptions!$B$57)-Assumptions!$B$16*$G$7*Assumptions!$B$38 -> 90.37 | H10: =$F10-'Fixed Operating Costs'!$G$20-(Assumptions!$B$14+Assumptions!$B$60)*Assumptions!$B$42-(Assumptions!$B$13*$H$7+Assumptions!$B$59)*Assumptions!$B$41-MIN(Assumptions!$B$72+MAX(0,(Assumptions!$B$13*$H$7+Assumptions!$B$59)-Assumptions!$C$72)*Assumptions!$D$72,Assumptions!$B$73+MAX(0,(Assumptions!$B$13*$H$7+Assumptions!$B$59)-Assumptions!$C$73)*Assumptions!$D$73,Assumptions!$B$74+MAX(0,(Assumptions!$B$13*$H$7+Assumptions!$B$59)-Assumptions!$C$74)*Assumptions!$D$74)-(Assumptions!$B$13*$H$7+Assumptions!$B$59)*((Assumptions!$B$47*Assumptions!$B$45/1000000)+(Assumptions!$B$48*Assumptions!$B$46/1000000))-MAX(0,(((Assumptions!$B$13*$H$7+Assumptions!$B$59)/Assumptions!$B$15)*Assumptions!$B$52+((Assumptions!$B$13*$H$7+Assumptions!$B$59)/Assumptions!$B$15)*Assumptions!$B$33*Assumptions!$B$53)-Assumptions!$B$50)*Assumptions!$B$51-$F10*Assumptions!$B$61-(Assumptions!$B$55+Assumptions!$B$57)-Assumptions!$B$16*$H$7*Assumptions!$B$38 -> 77.6575 | I10: =$F10-'Fixed Operating Costs'!$G$20-(Assumptions!$B$14+Assumptions!$B$60)*Assumptions!$B$42-(Assumptions!$B$13*$I$7+Assumptions!$B$59)*Assumptions!$B$41-MIN(Assumptions!$B$72+MAX(0,(Assumptions!$B$13*$I$7+Assumptions!$B$59)-Assumptions!$C$72)*Assumptions!$D$72,Assumptions!$B$73+MAX(0,(Assumptions!$B$13*$I$7+Assumptions!$B$59)-Assumptions!$C$73)*Assumptions!$D$73,Assumptions!$B$74+MAX(0,(Assumptions!$B$13*$I$7+Assumptions!$B$59)-Assumptions!$C$74)*Assumptions!$D$74)-(Assumptions!$B$13*$I$7+Assumptions!$B$59)*((Assumptions!$B$47*Assumptions!$B$45/1000000)+(Assumptions!$B$48*Assumptions!$B$46/1000000))-MAX(0,(((Assumptions!$B$13*$I$7+Assumptions!$B$59)/Assumptions!$B$15)*Assumptions!$B$52+((Assumptions!$B$13*$I$7+Assumptions!$B$59)/Assumptions!$B$15)*Assumptions!$B$33*Assumptions!$B$53)-Assumptions!$B$50)*Assumptions!$B$51-$F10*Assumptions!$B$61-(Assumptions!$B$55+Assumptions!$B$57)-Assumptions!$B$16*$I$7*Assumptions!$B$38 -> 57.86
